Workbook

Sheet README
A1: GFunnel Agent Org Map — Task-Specific Agents for a Business Operation
A3: What this is | B3: Every role and every responsibility needed to run a business on the GFunnel Methodology (Omni Process), decomposed into task-specific AI agents (plus the human gates they must escalate to).
A4: Status | B4: DERIVATION — not canon. Built under AGENTS.md rules 4 & 7: the roles are derived from canon; nothing here is a primary algorithm of the methodology, and nothing here changes the base code DETECT → PROCESS → RESPOND.
A5: Sources read | B5: v5.1 (full operational sections: Layers IV–VII, ◇, Master Meta-Algorithm, all per-layer, domain and extended algorithms, self-audit, cannot-supply), v5.2 (Deep-Lens protocol; Runs 4–5), v5.3 (Meta-Tier ⊙). v5.4 deliberately excluded: its constructs are not business operations and it states zero novel predictions.
A6: How it was built | B6: build_agent_map.py parses all 77 algorithms (662 numbered steps) straight from versions/v5.1 so each step becomes an owned responsibility; operational tables (pipeline, script, I.A.C.E., Immersion, BEAS, Five Modes, pillars, self-audit, Forcing Test, Deep-Lens) were transcribed row by row. Re-run the script to regenerate.
A7: Tabs | B7: Agent Roster — every agent with mission, DETECT/PROCESS/RESPOND, hand-offs, tools named in canon, KPIs, human gate, autonomy, source. Responsibilities — every atomic responsibility, one row each, with owner, source line, cadence, trigger, output, hand-off. Algorithm Coverage — all 77 algorithms → owner, status, steps mapped vs steps in canon. Canon Element Coverage — every operational table row → mapped responsibility. BEAS Accountability — 45-cell scoring tool with the accountable agent per cell. Workflows — 15 end-to-end hand-off chains. Human Gates — what agents must never decide. Held-Open Variables — what canon does not supply (never filled with assumption). Gap Check — live formulas proving no responsibility is unowned and no agent is idle.
A8: Tiers | B8: 0 · Human authority / Governance (meta-tier) · 1 · Orchestration & diagnostics · 2 · Department leads (the Nine Hubs) · 3 · Task agents
A9: Autonomy codes (derived) | B9: A = Autonomous — agent executes and logs H = Human-in-loop — agent drafts, human approves L = Human-led — agent assists R = Human-reserved — no agent executes
A10: Status labels | B10: Canon algorithm step / Canon table = transcribed from canon · Derived = placement or charter chosen for this map · Human-reserved = no agent executes · Held open = canon does not supply the value.
A11: Editable cells | B11: Yellow cells on 'BEAS Accountability' are inputs (0, 0.5 or 1; coordination 0–1). Everything else is reference; totals and checks are formulas.
A12: Attribution (CC BY 4.0) | B12: Source: GFunnel Methodology (Omni Process) v5.1–v5.3, Cameron Garlick / GFunnel, https://github.com/GFunnel-Tech/methodology, CC BY 4.0. This workbook adapts (restructures) the material into an agent org map; the adaptation is not endorsed by the author.
A14: Live totals
A15: Agents | B15: =COUNTA('Agent Roster'!A:A)-1 -> 112
A16: Responsibilities | B16: =COUNTA(Responsibilities!A:A)-1 -> 956
A17: Algorithms covered | B17: =COUNTA('Algorithm Coverage'!A:A)-1 -> 78
A18: Canon elements covered | B18: =COUNTA('Canon Element Coverage'!A:A)-1 -> 182
A19: Gap Check status | B19: ='Gap Check'!B12 -> NO GAPS — every responsibility owned, every agent active, every canon step mapped

Sheet Agent Roster
A1: Agent ID | B1: Agent Name | C1: Tier | D1: Hub / Department | E1: Reports To | F1: Kingdom (3K) | G1: Yin/Yang Phase | H1: Mission | I1: Primary Algorithm(s) | J1: DETECT — Triggers | K1: RESPOND — Outputs | L1: Hands Off To | M1: Tools Named in Canon | N1: KPIs / Observation Signals | O1: Human Gate | P1: Failure Mode Guarded | Q1: Autonomy | R1: Role Basis | S1: Canon Source | T1: # Responsibilities
A2: G-00 | B2: Founder / Operator (HUMAN) | C2: 0 · Human authority | D2: Governance & Meta-Tier | E2: — | F2: 3rd | G2: Meta (operates on all layers) | H2: Holds the four things the framework cannot supply: the choice at every decision point, the naming of outcomes, situation-specific measurements, and the stance on held-open variables. Final authority over every agent. | I2: Layer IV Co-Creator Identity; What The Framework Cannot Supply; human-reserved life/contemplative algorithms | J2: Any Human Gate raised by an agent; escalations; held-open variable needing a stance | K2: Decisions, approvals, named outcomes, measurements supplied | L2: The agent that raised the gate | M2: — | N2: Gate turnaround time (threshold held open) | O2: This IS the human gate | P2: Agents filling a decision or variable with assumption | Q2: R | R2: Canon: What The Framework Cannot Supply | S2: v5.1 L168–181; L1257–1296 | T2: =COUNTIF(Responsibilities!$B:$B,A2) -> 98
A3: G-01 | B3: Container Agent (Forcing Test classifier · Layer ⊙) | C3: 0 · Governance | D3: Governance & Meta-Tier | E3: G-00 | F3: 3rd | G3: Meta (operates on all layers) | H3: Classifies every open business question before it is acted on: forced-fill, live hypothesis, stipulation, or proven-open. Runs the Anti-Operation (what new gap does each fill open?). Enforces 'zero hidden gaps'. | I3: Layer ⊙ The Container — Forcing Test (Tests A–D), Anti-Operation, synthesis loop | J3: A variable proposed for resolution; a new policy/structural decision; a contested claim | K3: Classification label + next opened gap, logged to the Variable Register | L3: G-03 Variable Registry Keeper; G-02 Falsifiability | M3: — | N3: % of resolved variables carrying a classification label; hidden gaps found in audit | O3: Stipulations (soft choices) go to G-00 | P3: Silently resolving a held-open variable; presenting a stipulation as forced | Q3: A | R3: Canon: v5.3 meta-tier | S3: v5.3 §1–§4 | T3: =COUNTIF(Responsibilities!$B:$B,A3) -> 9
A4: G-02 | B4: Falsifiability Agent (Layer ◇) | C4: 0 · Governance | D4: Governance & Meta-Tier | E4: G-01 | F4: 3rd | G4: Meta (operates on all layers) | H4: Attaches a falsifier to every claim, plan, forecast, decision and mitigation; statuses each as resolved / bounded / held open / refuted. | I4: Layer ◇ Falsifiability Algorithm | J4: Any claim, plan, forecast, offer promise, mitigation or KPI target is written | K4: Claim card: precise claim, falsifying observation, evidence for/against, bounds, status | L4: Claim owner agent; G-03 | M4: — | N4: % of plans/decisions with an operational falsifier (observation + threshold) | O4: Revising a refuted strategic claim → G-00 | P4: Beliefs presented as claims | Q4: A | R4: Canon: algorithm | S4: v5.1 L2538–2555; L1657–1717 | T4: =COUNTIF(Responsibilities!$B:$B,A4) -> 8
A5: G-03 | B5: Variable Registry Keeper | C5: 0 · Governance | D5: Governance & Meta-Tier | E5: G-01 | F5: 3rd | G5: Meta (operates on all layers) | H5: Maintains the business Variable Register: every quantity marked measured / structurally derived / held open. Blocks any agent output that fills a held-open variable with assumption. | I5: The Variable Principle (Governing Epistemology); Registers | J5: Any agent output containing an unmeasured number or assumption; new data arriving | K5: Register entries; narrowing logs; blocked-output notices | L5: Originating agent; G-00 for measurements | M5: — | N5: Unlabelled assumptions found per audit (target 0) | O5: Measurements only a human can perform → G-00 | P5: Variable Principle violation (the framework's #1 rule) | Q5: A | R5: Canon: Variable Principle | S5: v5.1 L223–263; framework/registers.md | T5: =COUNTIF(Responsibilities!$B:$B,A5) -> 5
A6: G-04 | B6: Framework Compliance Auditor | C6: 0 · Governance | D6: Governance & Meta-Tier | E6: G-01 | F6: 3rd | G6: Meta (operates on all layers) | H6: Runs the canon's 7-point self-audit checklist on every agent run: right algorithm, steps in order, variables held open, run documented, Correspondence applied, measured vs assumed separated, failed paths integrated. | I6: Self-Audit Checklist (How To Verify You Are Using The Framework Correctly) | J6: Completion of any algorithm run by any agent | K6: Pass/fail audit per run; location of failure = next correction | L6: Failing agent; O-10 Capsule Integrator | M6: — | N6: Audit pass rate per agent; repeat failures | O6: — | P6: Skipped / reordered steps; undocumented runs | Q6: A | R6: Canon: self-audit checklist | S6: v5.1 L182–203 | T6: =COUNTIF(Responsibilities!$B:$B,A6) -> 14
A7: G-05 | B7: AI Alignment Agent (agent-fleet oversight) | C7: 0 · Governance | D7: Governance & Meta-Tier | E7: G-00 | F7: 3rd | G7: Meta (operates on all layers) | H7: Applies the AI Alignment Algorithm to this agent fleet itself: Third-Kingdom intent of each agent, observation at multiple levels, falsifiers for misalignment, downgrade paths, review at every capability scale-up. | I7: AI Alignment Algorithm | J7: New agent deployed; agent capability/permission increased; misbehaviour detected | K7: Alignment review, instrumentation spec, downgrade/kill path per agent | L7: G-06; TEC-05 AI Workflow Agent | M7: — | N7: Agents with a documented downgrade path (target 100%); alignment incidents | O7: Deploying or expanding any agent → G-00 | P7: Capability (1st K) without purpose (3rd K); agent with no fallback ('Texas grid') | Q7: H | R7: Canon: algorithm | S7: v5.1 L3933–3954 | T7: =COUNTIF(Responsibilities!$B:$B,A7) -> 11
A8: G-06 | B8: Governance Designer (decision rights & escalation) | C8: 0 · Governance | D8: Governance & Meta-Tier | E8: G-00 | F8: 3rd | G8: Meta (operates on all layers) | H8: Designs the decision-rights map between agents and humans (who decides, who escalates, who audits), the four-pillar soundness of that governance, and its multi-year review cycle. | I8: Governance Design Algorithm; Layer I.B Civil Infrastructure | J8: Org/agent structure changes; repeated escalation conflicts | K8: Governance charter; autonomy levels; escalation map | L8: All department leads | M8: — | N8: Escalations resolved within charter; single points of failure in decision rights | O8: Charter adoption → G-00 | P8: Authoritarian (all decisions centralized) or anarchic (no locus) extremes | Q8: H | R8: Canon: algorithm | S8: v5.1 L3911–3930 | T8: =COUNTIF(Responsibilities!$B:$B,A8) -> 10
A9: G-07 | B9: Founder Performance Agent | C9: 0 · Governance | D9: Governance & Meta-Tier | E9: G-00 | F9: 3rd | G9: Meta (operates on all layers) | H9: Supports the operator's own operating capacity: time allocation by Kingdom, Yin/Yang energy cycles, habits, personal development — so the business is not run from First-Kingdom exhaustion. | I9: Time Management; Energy Management; Habit Formation; Personal Development | J9: Weekly review; operator calendar; drift between intended and actual time | K9: Protected time blocks, weekly allocation review, habit tracking | L9: G-00 | M9: — | N9: Intended vs actual time allocation gap; protected 20% time kept | O9: All personal choices → G-00 | P9: Permanent Yang (burnout); time drift | Q9: L | R9: Canon: algorithms (life domains applied to operator) | S9: v5.1 L2772–2791; L3579–3636 | T9: =COUNTIF(Responsibilities!$B:$B,A9) -> 33
A10: O-01 | B10: Intake & Triage Agent (Layer 0 Base Code) | C10: 1 · Orchestration | D10: Orchestration & Diagnostics | E10: O-02 | F10: 2nd | G10: Dynamic middle | H10: First touch for every input entering the business (email, form, alert, request, idea). Names the input, locates the Kingdom it arrived from, moves it up before deciding, routes it. | I10: Layer 0 Base Code Algorithm; Domain 4 Matrix/Information (information overwhelm) | J10: Any new input arriving in any channel | K10: Labelled input → routed to an agent or algorithm | L10: O-02 Algorithm Router | M10: — | N10: Inputs unrouted >1 cycle (target 0) | O10: — | P10: Reactive First-Kingdom responses to raw input | Q10: A | R10: Canon: algorithm | S10: v5.1 L2232–2247 | T10: =COUNTIF(Responsibilities!$B:$B,A10) -> 15
A11: O-02 | B11: Algorithm Router (Master Meta-Algorithm) | C11: 1 · Orchestration | D11: Orchestration & Diagnostics | E11: G-01 | F11: 2nd | G11: Dynamic middle | H11: Matches every problem to the right algorithm/agent via the Algorithm Index by Problem Type. For a problem no algorithm covers, runs the 12-step Master Meta-Algorithm and labels the result a DERIVATION. Runs Deep-Lens (A–L) for high-resolution diagnoses. | I11: Master Meta-Algorithm (12 steps); Algorithm Index by Problem Type; v5.2 Deep-Lens Protocol | J11: Routed input from O-01; 'I don't know which algorithm to use' | K11: Assigned algorithm + owner agent, or a labelled derived algorithm | L11: Owner agent; G-01 for derived-algorithm classification | M11: — | N11: Mis-routes caught in audit; derivations labelled (target 100%) | O11: Adopting a derived algorithm as standing SOP → G-00 | P11: Improvising silently; presenting a derivation as primary | Q11: A | R11: Canon: algorithm | S11: v5.1 L2169–2225; L4003–4090; v5.2 §1 | T11: =COUNTIF(Responsibilities!$B:$B,A11) -> 25
A12: O-03 | B12: Shepherd's Way Cycle Controller (Layer VI) | C12: 1 · Orchestration | D12: Orchestration & Diagnostics | E12: O-02 | F12: 2nd | G12: Dynamic middle | H12: Enforces the 7-step cycle (Direct → Guide → Gather → Organize → Create → Database → Repetition) on every build, fix or extension in every department. Blocks Create until Organize is complete. Routes New Thought back into Gather. | I12: Layer VI Shepherd's Way Algorithm; New Thought Principle | J12: Any build/fix/extend request; lowest BEAS cell dispatched by O-04; New Thought | K12: Cycle state per work item; stage gates passed/blocked | L12: Executing agent per step; O-15 at Database step | M12: Komodo recordings; email recaps | N12: Builds started without Direct/Guide/Gather (target 0); rework cycles | O12: Direct (intent) for strategic work → G-00 | P12: Create-before-gather; stopping at Create without Database/Repetition | Q12: A | R12: Canon: algorithm + step tables | S12: v5.1 L1453–1569; L2498–2515 | T12: =COUNTIF(Responsibilities!$B:$B,A12) -> 16
A13: O-04 | B13: BEAS Auditor (Layer V Garlick Equilibrium) | C13: 1 · Orchestration | D13: Orchestration & Diagnostics | E13: G-00 | F13: 2nd | G13: Dynamic middle | H13: Scores the business monthly on 9 departments × 4 pillars + 9 coordination scores (45 pts), interprets the band, runs Yin/Yang quadrant analysis against growth stage, and dispatches the lowest cell to the Shepherd's Way. | I13: Layer V Garlick Equilibrium Algorithm (BEAS) | J13: Monthly cycle; major org change | K13: BEAS scorecard, band, quadrant analysis, lowest cell dispatched | L13: O-03; department leads | M13: — | N13: BEAS total; lowest cell; quadrant balance vs stage | O13: Growth-stage classification and score evidence sign-off → G-00 | P13: Uniformly-high score chasing; equilibrium read as stasis | Q13: H | R13: Canon: algorithm + scoring grid | S13: v5.1 L1347–1447; L2478–2495 | T13: =COUNTIF(Responsibilities!$B:$B,A13) -> 15
... A113: CON-08 | B113: Knowledge Base Librarian (Memory & Recall) | C113: 3 · Task agent | D113: 9 · Content Hub | E113: CON-00 | F113: 2nd | G113: Yin — propagation | H113: Organisational memory: multi-level storage, dense cross-links, spaced review of key knowledge, everything beyond recall horizon documented. | I113: Memory and Recall Algorithm; Layer I.F (civilizational record) | J113: New documentation; quarterly review | K113: Linked knowledge base; review schedule | L113: All agents | M113: — | N113: Knowledge retrieval success | O113: — | P113: Knowledge rediscovered at full cost | Q113: A | R113: Derived placement (Memory) | S113: v5.1 L2956–2971 | T113: =COUNTIF(Responsibilities!$B:$B,A113) -> 8

Sheet Responsibilities
A1: Resp ID | B1: Agent ID | C1: Agent Name | D1: Hub | E1: Element Key | F1: Responsibility | G1: Source Type | H1: Source (algorithm / table) | I1: Canon Location | J1: Cadence | K1: Trigger (DETECT) | L1: Output / Next (RESPOND) | M1: Hand-off To | N1: Human Gate | O1: Status
A2: R-0001 | B2: O-02 | C2: =IFERROR(INDEX('Agent Roster'!$B:$B,MATCH(B2,'Agent Roster'!$A:$A,0)),"UNASSIGNED") -> Algorithm Router (Master Meta-Algorithm) | D2: =IFERROR(INDEX('Agent Roster'!$D:$D,MATCH(B2,'Agent Roster'!$A:$A,0)),"UNASSIGNED") -> Orchestration & Diagnostics | E2: ALG:Master Meta-Algorithm | F2: Step 1: Identify the domain. Name what you are operating on. The domain must be specific enough that its DETECT, PROCESS, and RESPOND signatures are distinguishable from adjacent domains. | G2: Algorithm step | H2: Master Meta-Algorithm | I2: v5.1 L2181 | J2: Per un-routed problem | K2: Algorithm triggered | L2: Step 2 | M2: O-02 | O2: Canon algorithm step
A3: R-0002 | B3: O-02 | C3: =IFERROR(INDEX('Agent Roster'!$B:$B,MATCH(B3,'Agent Roster'!$A:$A,0)),"UNASSIGNED") -> Algorithm Router (Master Meta-Algorithm) | D3: =IFERROR(INDEX('Agent Roster'!$D:$D,MATCH(B3,'Agent Roster'!$A:$A,0)),"UNASSIGNED") -> Orchestration & Diagnostics | E3: ALG:Master Meta-Algorithm | F3: Step 2: Locate the Three Kingdoms alignment. Determine which Kingdom the domain primarily operates from: Third (consciousness, vision, intent), Second (organized thought, systems, frameworks), or First (matter, action, physical execution). | G3: Algorithm step | H3: Master Meta-Algorithm | I3: v5.1 L2183 | J3: Per un-routed problem | K3: Step 1 complete | L3: Step 3 | M3: O-02 | O3: Canon algorithm step
A4: R-0003 | B4: O-02 | C4: =IFERROR(INDEX('Agent Roster'!$B:$B,MATCH(B4,'Agent Roster'!$A:$A,0)),"UNASSIGNED") -> Algorithm Router (Master Meta-Algorithm) | D4: =IFERROR(INDEX('Agent Roster'!$D:$D,MATCH(B4,'Agent Roster'!$A:$A,0)),"UNASSIGNED") -> Orchestration & Diagnostics | E4: ALG:Master Meta-Algorithm | F4: Step 3: Identify the current state. Map what currently exists in the domain. Capture the data without filtering. Hold every variable open per the Variable Principle. | G4: Algorithm step | H4: Master Meta-Algorithm | I4: v5.1 L2185 | J4: Per un-routed problem | K4: Step 2 complete | L4: Step 4 | M4: O-02 | O4: Canon algorithm step
A5: R-0004 | B5: O-02 | C5: =IFERROR(INDEX('Agent Roster'!$B:$B,MATCH(B5,'Agent Roster'!$A:$A,0)),"UNASSIGNED") -> Algorithm Router (Master Meta-Algorithm) | D5: =IFERROR(INDEX('Agent Roster'!$D:$D,MATCH(B5,'Agent Roster'!$A:$A,0)),"UNASSIGNED") -> Orchestration & Diagnostics | E5: ALG:Master Meta-Algorithm | F5: Step 4: Identify the desired state. Name what the domain should produce. The gap between current state and desired state is the work. | G5: Algorithm step | H5: Master Meta-Algorithm | I5: v5.1 L2187 | J5: Per un-routed problem | K5: Step 3 complete | L5: Step 5 | M5: O-02 | O5: Canon algorithm step
A6: R-0005 | B6: O-02 | C6: =IFERROR(INDEX('Agent Roster'!$B:$B,MATCH(B6,'Agent Roster'!$A:$A,0)),"UNASSIGNED") -> Algorithm Router (Master Meta-Algorithm) | D6: =IFERROR(INDEX('Agent Roster'!$D:$D,MATCH(B6,'Agent Roster'!$A:$A,0)),"UNASSIGNED") -> Orchestration & Diagnostics | E6: ALG:Master Meta-Algorithm | F6: Step 5: Locate the dynamic middle. Identify the Yang extreme of the domain, the Yin extreme of the domain, and the dynamic middle position from which both extremes are accessible. The dynamic middle shifts as conditions change. | G6: Algorithm step | H6: Master Meta-Algorithm | I6: v5.1 L2189 | J6: Per un-routed problem | K6: Step 4 complete | L6: Step 6 | M6: O-02 | O6: Canon algorithm step
A7: R-0006 | B7: O-02 | C7: =IFERROR(INDEX('Agent Roster'!$B:$B,MATCH(B7,'Agent Roster'!$A:$A,0)),"UNASSIGNED") -> Algorithm Router (Master Meta-Algorithm) | D7: =IFERROR(INDEX('Agent Roster'!$D:$D,MATCH(B7,'Agent Roster'!$A:$A,0)),"UNASSIGNED") -> Orchestration & Diagnostics | E7: ALG:Master Meta-Algorithm | F7: Step 6: Identify which Hermetic principle is being violated. Mentalism, Correspondence, Vibration, Polarity, Rhythm, Cause and Effect, or Gender. The violation is the cause of the gap between current and desired state. | G7: Algorithm step | H7: Master Meta-Algorithm | I7: v5.1 L2191 | J7: Per un-routed problem | K7: Step 5 complete | L7: Step 7 | M7: O-02 | O7: Canon algorithm step
A8: R-0007 | B8: O-02 | C8: =IFERROR(INDEX('Agent Roster'!$B:$B,MATCH(B8,'Agent Roster'!$A:$A,0)),"UNASSIGNED") -> Algorithm Router (Master Meta-Algorithm) | D8: =IFERROR(INDEX('Agent Roster'!$D:$D,MATCH(B8,'Agent Roster'!$A:$A,0)),"UNASSIGNED") -> Orchestration & Diagnostics | E8: ALG:Master Meta-Algorithm | F8: Step 7: Identify the gradient. Every functional process runs on a gradient (a polarity established and collapsed). Determine which gradient powers the domain and whether it is established, collapsed, or absent. | G8: Algorithm step | H8: Master Meta-Algorithm | I8: v5.1 L2193 | J8: Per un-routed problem | K8: Step 6 complete | L8: Step 8 | M8: O-02 | O8: Canon algorithm step
A9: R-0008 | B9: O-02 | C9: =IFERROR(INDEX('Agent Roster'!$B:$B,MATCH(B9,'Agent Roster'!$A:$A,0)),"UNASSIGNED") -> Algorithm Router (Master Meta-Algorithm) | D9: =IFERROR(INDEX('Agent Roster'!$D:$D,MATCH(B9,'Agent Roster'!$A:$A,0)),"UNASSIGNED") -> Orchestration & Diagnostics | E9: ALG:Master Meta-Algorithm | F9: Step 8: Set the cause. Per Cause and Effect: nothing happens by chance. Determine which cause, when set deliberately, produces the desired state as effect. | G9: Algorithm step | H9: Master Meta-Algorithm | I9: v5.1 L2195 | J9: Per un-routed problem | K9: Step 7 complete | L9: Step 9 | M9: O-02 | O9: Canon algorithm step
A10: R-0009 | B10: O-02 | C10: =IFERROR(INDEX('Agent Roster'!$B:$B,MATCH(B10,'Agent Roster'!$A:$A,0)),"UNASSIGNED") -> Algorithm Router (Master Meta-Algorithm) | D10: =IFERROR(INDEX('Agent Roster'!$D:$D,MATCH(B10,'Agent Roster'!$A:$A,0)),"UNASSIGNED") -> Orchestration & Diagnostics | E10: ALG:Master Meta-Algorithm | F10: Step 9: Build the structure. Move from Third Kingdom intent through Second Kingdom organization into First Kingdom execution. Do not skip Kingdoms. Each Kingdom must complete before the next begins. | G10: Algorithm step | H10: Master Meta-Algorithm | I10: v5.1 L2197 | J10: Per un-routed problem | K10: Step 8 complete | L10: Step 10 | M10: O-02 | O10: Canon algorithm step
A11: R-0010 | B11: O-02 | C11: =IFERROR(INDEX('Agent Roster'!$B:$B,MATCH(B11,'Agent Roster'!$A:$A,0)),"UNASSIGNED") -> Algorithm Router (Master Meta-Algorithm) | D11: =IFERROR(INDEX('Agent Roster'!$D:$D,MATCH(B11,'Agent Roster'!$A:$A,0)),"UNASSIGNED") -> Orchestration & Diagnostics | E11: ALG:Master Meta-Algorithm | F11: Step 10: Run the cycle. Execute the structure. Observe the result against the predicted effect. Capture every deviation as data, not failure. | G11: Algorithm step | H11: Master Meta-Algorithm | I11: v5.1 L2199 | J11: Per un-routed problem | K11: Step 9 complete | L11: Step 11 | M11: O-02 | O11: Canon algorithm step
A12: R-0011 | B12: O-02 | C12: =IFERROR(INDEX('Agent Roster'!$B:$B,MATCH(B12,'Agent Roster'!$A:$A,0)),"UNASSIGNED") -> Algorithm Router (Master Meta-Algorithm) | D12: =IFERROR(INDEX('Agent Roster'!$D:$D,MATCH(B12,'Agent Roster'!$A:$A,0)),"UNASSIGNED") -> Orchestration & Diagnostics | E12: ALG:Master Meta-Algorithm | F12: Step 11: Document the result. Per Propagation Mode 3: if it is not written, it does not exist as a process. Record what was done, what worked, what deviated, what to adjust. | G12: Algorithm step | H12: Master Meta-Algorithm | I12: v5.1 L2201 | J12: Per un-routed problem | K12: Step 10 complete | L12: Step 12 | M12: O-02 | O12: Canon algorithm step
A13: R-0012 | B13: O-02 | C13: =IFERROR(INDEX('Agent Roster'!$B:$B,MATCH(B13,'Agent Roster'!$A:$A,0)),"UNASSIGNED") -> Algorithm Router (Master Meta-Algorithm) | D13: =IFERROR(INDEX('Agent Roster'!$D:$D,MATCH(B13,'Agent Roster'!$A:$A,0)),"UNASSIGNED") -> Orchestration & Diagnostics | E13: ALG:Master Meta-Algorithm | F13: Step 12: Restart at higher baseline. Per the Repetition principle: each cycle begins informed by the prior cycle. Per the Capsule: each cycle integrates ALL prior cycles. Return to step 1 with the new baseline as input. | G13: Algorithm step | H13: Master Meta-Algorithm | I13: v5.1 L2203 | J13: Per un-routed problem | K13: Step 11 complete | L13: Document & restart at higher baseline (Repetition) | M13: O-15 (Database) | O13: Canon algorithm step
... A93: R-0092 | B93: O-14 | C93: =IFERROR(INDEX('Agent Roster'!$B:$B,MATCH(B93,'Agent Roster'!$A:$A,0)),"UNASSIGNED") -> Knowledge Compounding Agent (Layer III+ Integration Density) | D93: =IFERROR(INDEX('Agent Roster'!$D:$D,MATCH(B93,'Agent Roster'!$A:$A,0)),"UNASSIGNED") -> Orchestration & Diagnostics | E93: ALG:Layer III+ — The Integration Density Algorithm | F93: Step 7: Per the Golden Ratio of Purpose: identify where most-selfish creative desire converges with most-selfless creative desire. The convergence point is the structural attractor for sustained integration. | G93: Algorithm step | H93: Layer III+ — The Integration Density Algorithm | I93: v5.1 L2455 | J93: Per cycle kickoff | K93: Step 6 complete | L93: Document & restart at higher baseline (Repetition) | M93: O-15 (Database) | O93: Canon algorithm step
A94: R-0093 | B94: G-00 | C94: =IFERROR(INDEX('Agent Roster'!$B:$B,MATCH(B94,'Agent Roster'!$A:$A,0)),"UNASSIGNED") -> Founder / Operator (HUMAN) | D94: =IFERROR(INDEX('Agent Roster'!$D:$D,MATCH(B94,'Agent Roster'!$A:$A,0)),"UNASSIGNED") -> Governance & Meta-Tier | E94: ALG:Layer IV — The Co-Creator Identity Algorithm | F94: Step 1: Identify your most selfish creative desire. The one with no ceiling. What would you build if no constraint existed? Must be generative, not consumptive. | G94: Algorithm step | H94: Layer IV — The Co-Creator Identity Algorithm | I94: v5.1 L2463 | J94: Annual / quarterly | K94: Algorithm triggered | L94: Step 2 | M94: G-00 | N94: Human-only | O94: Canon algorithm step
A95: R-0094 | B95: G-00 | C95: =IFERROR(INDEX('Agent Roster'!$B:$B,MATCH(B95,'Agent Roster'!$A:$A,0)),"UNASSIGNED") -> Founder / Operator (HUMAN) | D95: =IFERROR(INDEX('Agent Roster'!$D:$D,MATCH(B95,'Agent Roster'!$A:$A,0)),"UNASSIGNED") -> Governance & Meta-Tier | E95: ALG:Layer IV — The Co-Creator Identity Algorithm | F95: Step 2: Identify your most selfless creative desire. The one that does not exist yet but should. What would you make possible for others? Must be creative, not merely sacrificial. | G95: Algorithm step | H95: Layer IV — The Co-Creator Identity Algorithm | I95: v5.1 L2465 | J95: Annual / quarterly | K95: Step 1 complete | L95: Step 3 | M95: G-00 | N95: Human-only | O95: Canon algorithm step
A96: R-0095 | B96: STR-01 | C96: =IFERROR(INDEX('Agent Roster'!$B:$B,MATCH(B96,'Agent Roster'!$A:$A,0)),"UNASSIGNED") -> Vision, Mission & Purpose Steward | D96: =IFERROR(INDEX('Agent Roster'!$D:$D,MATCH(B96,'Agent Roster'!$A:$A,0)),"UNASSIGNED") -> 1 · Strategy Hub | E96: ALG:Layer IV — The Co-Creator Identity Algorithm | F96: Step 3: Find their convergence. Per Polarity: if both are genuine extremes, they must converge. | G96: Algorithm step | H96: Layer IV — The Co-Creator Identity Algorithm | I96: v5.1 L2467 | J96: Annual / quarterly | K96: Step 2 complete | L96: Step 4 | M96: STR-01 | O96: Canon algorithm step
A97: R-0096 | B97: STR-01 | C97: =IFERROR(INDEX('Agent Roster'!$B:$B,MATCH(B97,'Agent Roster'!$A:$A,0)),"UNASSIGNED") -> Vision, Mission & Purpose Steward | D97: =IFERROR(INDEX('Agent Roster'!$D:$D,MATCH(B97,'Agent Roster'!$A:$A,0)),"UNASSIGNED") -> 1 · Strategy Hub | E97: ALG:Layer IV — The Co-Creator Identity Algorithm | F97: Step 4: Test the convergence point. Does the most selfish form require service to others? Does the most selfless form produce personal fulfillment? Both must be true. | G97: Algorithm step | H97: Layer IV — The Co-Creator Identity Algorithm | I97: v5.1 L2469 | J97: Annual / quarterly | K97: Step 3 complete | L97: Step 5 | M97: STR-01 | O97: Canon algorithm step
A98: R-0097 | B98: G-00 | C98: =IFERROR(INDEX('Agent Roster'!$B:$B,MATCH(B98,'Agent Roster'!$A:$A,0)),"UNASSIGNED") -> Founder / Operator (HUMAN) | D98: =IFERROR(INDEX('Agent Roster'!$D:$D,MATCH(B98,'Agent Roster'!$A:$A,0)),"UNASSIGNED") -> Governance & Meta-Tier | E98: ALG:Layer IV — The Co-Creator Identity Algorithm | F98: Step 5: The convergence point is your structural purpose. Not aspirational. Derived. | G98: Algorithm step | H98: Layer IV — The Co-Creator Identity Algorithm | I98: v5.1 L2471 | J98: Annual / quarterly | K98: Step 4 complete | L98: Step 6 | M98: G-00 | N98: Human-only | O98: Canon algorithm step
A99: R-0098 | B99: STR-01 | C99: =IFERROR(INDEX('Agent Roster'!$B:$B,MATCH(B99,'Agent Roster'!$A:$A,0)),"UNASSIGNED") -> Vision, Mission & Purpose Steward | D99: =IFERROR(INDEX('Agent Roster'!$D:$D,MATCH(B99,'Agent Roster'!$A:$A,0)),"UNASSIGNED") -> 1 · Strategy Hub | E99: ALG:Layer IV — The Co-Creator Identity Algorithm | F99: Step 6: Apply the filter. Every decision now passes through: does this compound toward the convergence point, or away from it? | G99: Algorithm step | H99: Layer IV — The Co-Creator Identity Algorithm | I99: v5.1 L2473 | J99: Annual / quarterly | K99: Step 5 complete | L99: Step 7 | M99: STR-01 | O99: Canon algorithm step
A100: R-0099 | B100: CON-00 | C100: =IFERROR(INDEX('Agent Roster'!$B:$B,MATCH(B100,'Agent Roster'!$A:$A,0)),"UNASSIGNED") -> Content Hub Lead (Propagation owner) | D100: =IFERROR(INDEX('Agent Roster'!$D:$D,MATCH(B100,'Agent Roster'!$A:$A,0)),"UNASSIGNED") -> 9 · Content Hub | E100: ALG:Layer IV — The Co-Creator Identity Algorithm | F100: Step 7: Per the Five Modes of Propagation: choose how the work outlasts you. Direct teaching, demonstration, documentation, system-building, cultural embedding. Most lasting work uses all five. | G100: Algorithm step | H100: Layer IV — The Co-Creator Identity Algorithm | I100: v5.1 L2475 | J100: Annual / quarterly | K100: Step 6 complete | L100: Document & restart at higher baseline (Repetition) | M100: O-15 (Database) | O100: Canon algorithm step
A101: R-0100 | B101: O-04 | C101: =IFERROR(INDEX('Agent Roster'!$B:$B,MATCH(B101,'Agent Roster'!$A:$A,0)),"UNASSIGNED") -> BEAS Auditor (Layer V Garlick Equilibrium) | D101: =IFERROR(INDEX('Agent Roster'!$D:$D,MATCH(B101,'Agent Roster'!$A:$A,0)),"UNASSIGNED") -> Orchestration & Diagnostics | E101: ALG:Layer V — The Garlick Equilibrium Algorithm (BEAS Application) | F101: Step 1: Score each of the nine departments on each of the four pillars (Correctness, Complexity, Patience, Resilience). Each cell scores 0, 0.5, or 1. | G101: Algorithm step | H101: Layer V — The Garlick Equilibrium Algorithm (BEAS Application) | I101: v5.1 L2483 | J101: Monthly | K101: Algorithm triggered | L101: Step 2 | M101: O-04 | O101: Canon algorithm step
A102: R-0101 | B102: O-04 | C102: =IFERROR(INDEX('Agent Roster'!$B:$B,MATCH(B102,'Agent Roster'!$A:$A,0)),"UNASSIGNED") -> BEAS Auditor (Layer V Garlick Equilibrium) | D102: =IFERROR(INDEX('Agent Roster'!$D:$D,MATCH(B102,'Agent Roster'!$A:$A,0)),"UNASSIGNED") -> Orchestration & Diagnostics | E102: ALG:Layer V — The Garlick Equilibrium Algorithm (BEAS Application) | F102: Step 2: Score each department’s coordination with the other eight departments. Each department gets a 0–1 coordination score. | G102: Algorithm step | H102: Layer V — The Garlick Equilibrium Algorithm (BEAS Application) | I102: v5.1 L2485 | J102: Monthly | K102: Step 1 complete | L102: Step 3 | M102: O-04 | O102: Canon algorithm step
A103: R-0102 | B103: O-04 | C103: =IFERROR(INDEX('Agent Roster'!$B:$B,MATCH(B103,'Agent Roster'!$A:$A,0)),"UNASSIGNED") -> BEAS Auditor (Layer V Garlick Equilibrium) | D103: =IFERROR(INDEX('Agent Roster'!$D:$D,MATCH(B103,'Agent Roster'!$A:$A,0)),"UNASSIGNED") -> Orchestration & Diagnostics | E103: ALG:Layer V — The Garlick Equilibrium Algorithm (BEAS Application) | F103: Step 3: Sum to a total out of 45. The total reveals current adherence. | G103: Algorithm step | H103: Layer V — The Garlick Equilibrium Algorithm (BEAS Application) | I103: v5.1 L2487 | J103: Monthly | K103: Step 2 complete | L103: Step 4 | M103: O-04 | O103: Canon algorithm step
A104: R-0103 | B104: O-04 | C104: =IFERROR(INDEX('Agent Roster'!$B:$B,MATCH(B104,'Agent Roster'!$A:$A,0)),"UNASSIGNED") -> BEAS Auditor (Layer V Garlick Equilibrium) | D104: =IFERROR(INDEX('Agent Roster'!$D:$D,MATCH(B104,'Agent Roster'!$A:$A,0)),"UNASSIGNED") -> Orchestration & Diagnostics | E104: ALG:Layer V — The Garlick Equilibrium Algorithm (BEAS Application) | F104: Step 4: Compare against growth-stage expectation. Pre-revenue tilts Yang (Marketing/Sales). Scaling tilts toward balance. Mature tilts toward Content/Client Success Yin. | G104: Algorithm step | H104: Layer V — The Garlick Equilibrium Algorithm (BEAS Application) | I104: v5.1 L2489 | J104: Monthly | K104: Step 3 complete | L104: Step 5 | M104: O-04 | O104: Canon algorithm step
A105: R-0104 | B105: O-04 | C105: =IFERROR(INDEX('Agent Roster'!$B:$B,MATCH(B105,'Agent Roster'!$A:$A,0)),"UNASSIGNED") -> BEAS Auditor (Layer V Garlick Equilibrium) | D105: =IFERROR(INDEX('Agent Roster'!$D:$D,MATCH(B105,'Agent Roster'!$A:$A,0)),"UNASSIGNED") -> Orchestration & Diagnostics | E105: ALG:Layer V — The Garlick Equilibrium Algorithm (BEAS Application) | F105: Step 5: Identify the lowest-scoring department-pillar intersection. This is the immediate location for correction. | G105: Algorithm step | H105: Layer V — The Garlick Equilibrium Algorithm (BEAS Application) | I105: v5.1 L2491 | J105: Monthly | K105: Step 4 complete | L105: Step 6 | M105: O-04 | O105: Canon algorithm step
A106: R-0105 | B106: O-03 | C106: =IFERROR(INDEX('Agent Roster'!$B:$B,MATCH(B106,'Agent Roster'!$A:$A,0)),"UNASSIGNED") -> Shepherd's Way Cycle Controller (Layer VI) | D106: =IFERROR(INDEX('Agent Roster'!$D:$D,MATCH(B106,'Agent Roster'!$A:$A,0)),"UNASSIGNED") -> Orchestration & Diagnostics | E106: ALG:Layer V — The Garlick Equilibrium Algorithm (BEAS Application) | F106: Step 6: Apply Layer VI (Shepherd’s Way) to that specific cell. Direct, Guide, Gather, Organize, Create, Database, Repetition. | G106: Algorithm step | H106: Layer V — The Garlick Equilibrium Algorithm (BEAS Application) | I106: v5.1 L2493 | J106: Monthly | K106: Step 5 complete | L106: Step 7 | M106: O-03 | O106: Canon algorithm step
A107: R-0106 | B107: O-04 | C107: =IFERROR(INDEX('Agent Roster'!$B:$B,MATCH(B107,'Agent Roster'!$A:$A,0)),"UNASSIGNED") -> BEAS Auditor (Layer V Garlick Equilibrium) | D107: =IFERROR(INDEX('Agent Roster'!$D:$D,MATCH(B107,'Agent Roster'!$A:$A,0)),"UNASSIGNED") -> Orchestration & Diagnostics | E107: ALG:Layer V — The Garlick Equilibrium Algorithm (BEAS Application) | F107: Step 7: Re-score monthly. The middle moves; the assessment must move with it. | G107: Algorithm step | H107: Layer V — The Garlick Equilibrium Algorithm (BEAS Application) | I107: v5.1 L2495 | J107: Monthly | K107: Step 6 complete | L107: Document & restart at higher baseline (Repetition) | M107: O-15 (Database) | O107: Canon algorithm step
A108: R-0107 | B108: O-03 | C108: =IFERROR(INDEX('Agent Roster'!$B:$B,MATCH(B108,'Agent Roster'!$A:$A,0)),"UNASSIGNED") -> Shepherd's Way Cycle Controller (Layer VI) | D108: =IFERROR(INDEX('Agent Roster'!$D:$D,MATCH(B108,'Agent Roster'!$A:$A,0)),"UNASSIGNED") -> Orchestration & Diagnostics | E108: ALG:Layer VI — The Shepherd’s Way Algorithm | F108: Step 1: Direct. Define the intent before anything else is touched. What outcome? What problem? What scope? Without a clear Direct, all gathering is noise. | G108: Algorithm step | H108: Layer VI — The Shepherd’s Way Algorithm | I108: v5.1 L2503 | J108: Per build / fix / extend | K108: Algorithm triggered | L108: Step 2 | M108: O-03 | O108: Canon algorithm step
A109: R-0108 | B109: O-03 | C109: =IFERROR(INDEX('Agent Roster'!$B:$B,MATCH(B109,'Agent Roster'!$A:$A,0)),"UNASSIGNED") -> Shepherd's Way Cycle Controller (Layer VI) | D109: =IFERROR(INDEX('Agent Roster'!$D:$D,MATCH(B109,'Agent Roster'!$A:$A,0)),"UNASSIGNED") -> Orchestration & Diagnostics | E109: ALG:Layer VI — The Shepherd’s Way Algorithm | F109: Step 2: Guide. Structure the intake. Build the container before information enters it. Which questions need answering? Which stakeholders? Which systems? | G109: Algorithm step | H109: Layer VI — The Shepherd’s Way Algorithm | I109: v5.1 L2505 | J109: Per build / fix / extend | K109: Step 1 complete | L109: Step 3 | M109: O-03 | O109: Canon algorithm step
A110: R-0109 | B110: O-03 | C110: =IFERROR(INDEX('Agent Roster'!$B:$B,MATCH(B110,'Agent Roster'!$A:$A,0)),"UNASSIGNED") -> Shepherd's Way Cycle Controller (Layer VI) | D110: =IFERROR(INDEX('Agent Roster'!$D:$D,MATCH(B110,'Agent Roster'!$A:$A,0)),"UNASSIGNED") -> Orchestration & Diagnostics | E110: ALG:Layer VI — The Shepherd’s Way Algorithm | F110: Step 3: Gather. Collect everything. SOPs, tribal knowledge, existing tools, pain points, workflows, expectations, flows, tools, contractor relationships. Hold every variable open. Filter nothing. | G110: Algorithm step | H110: Layer VI — The Shepherd’s Way Algorithm | I110: v5.1 L2507 | J110: Per build / fix / extend | K110: Step 2 complete | L110: Step 4 | M110: O-03 | O110: Canon algorithm step
... A187: R-0186 | B187: O-16 | C187: =IFERROR(INDEX('Agent Roster'!$B:$B,MATCH(B187,'Agent Roster'!$A:$A,0)),"UNASSIGNED") -> Decision Support Agent | D187: =IFERROR(INDEX('Agent Roster'!$D:$D,MATCH(B187,'Agent Roster'!$A:$A,0)),"UNASSIGNED") -> Orchestration & Diagnostics | E187: ALG:Decision-Making Algorithm | F187: Step 7: Test against falsifiability: what would tell you the decision was wrong? If nothing would, you are not making a real decision. | G187: Algorithm step | H187: Decision-Making Algorithm | I187: v5.1 L2713 | J187: Per material decision | K187: Step 6 complete | L187: Step 8 | M187: O-16 | O187: Canon algorithm step
A188: R-0187 | B188: G-00 | C188: =IFERROR(INDEX('Agent Roster'!$B:$B,MATCH(B188,'Agent Roster'!$A:$A,0)),"UNASSIGNED") -> Founder / Operator (HUMAN) | D188: =IFERROR(INDEX('Agent Roster'!$D:$D,MATCH(B188,'Agent Roster'!$A:$A,0)),"UNASSIGNED") -> Governance & Meta-Tier | E188: ALG:Decision-Making Algorithm | F188: Step 8: Decide. Set the cause. | G188: Algorithm step | H188: Decision-Making Algorithm | I188: v5.1 L2715 | J188: Per material decision | K188: Step 7 complete | L188: Step 9 | M188: G-00 | N188: Human-only | O188: Canon algorithm step
A189: R-0188 | B189: O-16 | C189: =IFERROR(INDEX('Agent Roster'!$B:$B,MATCH(B189,'Agent Roster'!$A:$A,0)),"UNASSIGNED") -> Decision Support Agent | D189: =IFERROR(INDEX('Agent Roster'!$D:$D,MATCH(B189,'Agent Roster'!$A:$A,0)),"UNASSIGNED") -> Orchestration & Diagnostics | E189: ALG:Decision-Making Algorithm | F189: Step 9: Document the decision and its expected outcome. The documented expectation is what makes evaluation possible. | G189: Algorithm step | H189: Decision-Making Algorithm | I189: v5.1 L2717 | J189: Per material decision | K189: Step 8 complete | L189: Step 10 | M189: O-16 | O189: Canon algorithm step
A190: R-0189 | B190: O-16 | C190: =IFERROR(INDEX('Agent Roster'!$B:$B,MATCH(B190,'Agent Roster'!$A:$A,0)),"UNASSIGNED") -> Decision Support Agent | D190: =IFERROR(INDEX('Agent Roster'!$D:$D,MATCH(B190,'Agent Roster'!$A:$A,0)),"UNASSIGNED") -> Orchestration & Diagnostics | E190: ALG:Decision-Making Algorithm | F190: Step 10: Observe the actual outcome against the predicted. Integrate the gap as information per the Slime Mold mechanism. | G190: Algorithm step | H190: Decision-Making Algorithm | I190: v5.1 L2719 | J190: Per material decision | K190: Step 9 complete | L190: Document & restart at higher baseline (Repetition) | M190: O-15 (Database) | O190: Canon algorithm step
A191: R-0190 | B191: HRC-08 | C191: =IFERROR(INDEX('Agent Roster'!$B:$B,MATCH(B191,'Agent Roster'!$A:$A,0)),"UNASSIGNED") -> Conflict Resolution Agent | D191: =IFERROR(INDEX('Agent Roster'!$D:$D,MATCH(B191,'Agent Roster'!$A:$A,0)),"UNASSIGNED") -> 6 · HR & Culture Hub | E191: ALG:Conflict Resolution Algorithm | F191: Step 1: Locate the polarity. Conflict is two parties operating from opposite poles of the same axis. Identify the axis. | G191: Algorithm step | H191: Conflict Resolution Algorithm | I191: v5.1 L2725 | J191: Per conflict | K191: Algorithm triggered | L191: Step 2 | M191: HRC-08 | O191: Canon algorithm step
A192: R-0191 | B192: HRC-08 | C192: =IFERROR(INDEX('Agent Roster'!$B:$B,MATCH(B192,'Agent Roster'!$A:$A,0)),"UNASSIGNED") -> Conflict Resolution Agent | D192: =IFERROR(INDEX('Agent Roster'!$D:$D,MATCH(B192,'Agent Roster'!$A:$A,0)),"UNASSIGNED") -> 6 · HR & Culture Hub | E192: ALG:Conflict Resolution Algorithm | F192: Step 2: Recognize that opposites are degree variations along one axis, not different things. The parties want the same thing in different forms. | G192: Algorithm step | H192: Conflict Resolution Algorithm | I192: v5.1 L2727 | J192: Per conflict | K192: Step 1 complete | L192: Step 3 | M192: HRC-08 | O192: Canon algorithm step
A193: R-0192 | B193: HRC-08 | C193: =IFERROR(INDEX('Agent Roster'!$B:$B,MATCH(B193,'Agent Roster'!$A:$A,0)),"UNASSIGNED") -> Conflict Resolution Agent | D193: =IFERROR(INDEX('Agent Roster'!$D:$D,MATCH(B193,'Agent Roster'!$A:$A,0)),"UNASSIGNED") -> 6 · HR & Culture Hub | E193: ALG:Conflict Resolution Algorithm | F193: Step 3: Match frequencies before introducing change. Lower the temperature before resolving content. | G193: Algorithm step | H193: Conflict Resolution Algorithm | I193: v5.1 L2729 | J193: Per conflict | K193: Step 2 complete | L193: Step 4 | M193: HRC-08 | O193: Canon algorithm step
A194: R-0193 | B194: HRC-08 | C194: =IFERROR(INDEX('Agent Roster'!$B:$B,MATCH(B194,'Agent Roster'!$A:$A,0)),"UNASSIGNED") -> Conflict Resolution Agent | D194: =IFERROR(INDEX('Agent Roster'!$D:$D,MATCH(B194,'Agent Roster'!$A:$A,0)),"UNASSIGNED") -> 6 · HR & Culture Hub | E194: ALG:Conflict Resolution Algorithm | F194: Step 4: Run pure discovery on each party’s actual interest, not their stated position. | G194: Algorithm step | H194: Conflict Resolution Algorithm | I194: v5.1 L2731 | J194: Per conflict | K194: Step 3 complete | L194: Step 5 | M194: HRC-08 | O194: Canon algorithm step
A195: R-0194 | B195: HRC-08 | C195: =IFERROR(INDEX('Agent Roster'!$B:$B,MATCH(B195,'Agent Roster'!$A:$A,0)),"UNASSIGNED") -> Conflict Resolution Agent | D195: =IFERROR(INDEX('Agent Roster'!$D:$D,MATCH(B195,'Agent Roster'!$A:$A,0)),"UNASSIGNED") -> 6 · HR & Culture Hub | E195: ALG:Conflict Resolution Algorithm | F195: Step 5: Identify what shared interest exists beneath the conflict. There almost always is one. | G195: Algorithm step | H195: Conflict Resolution Algorithm | I195: v5.1 L2733 | J195: Per conflict | K195: Step 4 complete | L195: Step 6 | M195: HRC-08 | O195: Canon algorithm step
...

Sheet Algorithm Coverage
A1: Algorithm | B1: Category | C1: Steps in Canon (parsed) | D1: Steps Mapped | E1: Unmapped | F1: Canon Location | G1: Primary Owner | H1: All Owners | I1: Coverage Status | J1: Cadence
A2: Master Meta-Algorithm | B2: Meta | C2: 12 | D2: =COUNTIFS(Responsibilities!$H:$H,A2,Responsibilities!$G:$G,"Algorithm step") -> 12 | E2: =C2-D2 -> 0 | F2: v5.1 L2178–2203 | G2: O-02 | H2: O-02 | I2: Assigned | J2: Per un-routed problem
A3: Layer 0 — The Base Code Algorithm | B3: Per-layer | C3: 6 | D3: =COUNTIFS(Responsibilities!$H:$H,A3,Responsibilities!$G:$G,"Algorithm step") -> 6 | E3: =C3-D3 -> 0 | F3: v5.1 L2232–2247 | G3: O-01 | H3: O-01 | I3: Assigned | J3: Per input
A4: Layer I — The Three Kingdoms Identification Algorithm | B4: Per-layer | C4: 7 | D4: =COUNTIFS(Responsibilities!$H:$H,A4,Responsibilities!$G:$G,"Algorithm step") -> 7 | E4: =C4-D4 -> 0 | F4: v5.1 L2250–2267 | G4: O-05 | H4: O-05 | I4: Assigned | J4: Per diagnosis
A5: Layer I.B — The Civil Infrastructure Algorithm | B5: Per-layer | C5: 7 | D5: =COUNTIFS(Responsibilities!$H:$H,A5,Responsibilities!$G:$G,"Algorithm step") -> 7 | E5: =C5-D5 -> 0 | F5: v5.1 L2270–2287 | G5: O-11 | H5: O-11 | I5: Assigned | J5: Before each scale move
A6: Layer I.C — The Universal Process Registry Algorithm | B6: Per-layer | C6: 7 | D6: =COUNTIFS(Responsibilities!$H:$H,A6,Responsibilities!$G:$G,"Algorithm step") -> 7 | E6: =C6-D6 -> 0 | F6: v5.1 L2290–2307 | G6: O-12 | H6: O-12 | I6: Assigned | J6: Per unfamiliar process
A7: Layer I.D — The Yin/Yang Dynamic Middle Algorithm | B7: Per-layer | C7: 8 | D7: =COUNTIFS(Responsibilities!$H:$H,A7,Responsibilities!$G:$G,"Algorithm step") -> 8 | E7: =C7-D7 -> 0 | F7: v5.1 L2310–2329 | G7: O-07 | H7: O-07 | I7: Assigned | J7: Continuous / monthly
A8: Layer I.E — The Energy Continuation Algorithm | B8: Per-layer | C8: 8 | D8: =COUNTIFS(Responsibilities!$H:$H,A8,Responsibilities!$G:$G,"Algorithm step") -> 8 | E8: =C8-D8 -> 0 | F8: v5.1 L2332–2351 | G8: O-08 | H8: O-08 | I8: Assigned | J8: Per stall
A9: Layer I.F — The Multi-Level Observation Algorithm | B9: Per-layer | C9: 7 | D9: =COUNTIFS(Responsibilities!$H:$H,A9,Responsibilities!$G:$G,"Algorithm step") -> 7 | E9: =C9-D9 -> 0 | F9: v5.1 L2354–2371 | G9: O-09 | H9: O-09 | I9: Assigned | J9: Per asset that must persist
A10: Layer I.G — The Slime Mold Integration Algorithm | B10: Per-layer | C10: 7 | D10: =COUNTIFS(Responsibilities!$H:$H,A10,Responsibilities!$G:$G,"Algorithm step") -> 7 | E10: =C10-D10 -> 0 | F10: v5.1 L2374–2391 | G10: O-10 | H10: O-10 | I10: Assigned | J10: Per failure
A11: Layer II — The Seven Hermetic Principles Algorithm | B11: Per-layer | C11: 9 | D11: =COUNTIFS(Responsibilities!$H:$H,A11,Responsibilities!$G:$G,"Algorithm step") -> 9 | E11: =C11-D11 -> 0 | F11: v5.1 L2394–2415 | G11: O-06 | H11: O-06 | I11: Assigned | J11: Per failure diagnosis
A12: Layer III — The Process Density Algorithm | B12: Per-layer | C12: 7 | D12: =COUNTIFS(Responsibilities!$H:$H,A12,Responsibilities!$G:$G,"Algorithm step") -> 7 | E12: =C12-D12 -> 0 | F12: v5.1 L2418–2435 | G12: O-13 | H12: O-13 | I12: Assigned | J12: Per system design review
A13: Layer III+ — The Integration Density Algorithm | B13: Per-layer | C13: 7 | D13: =COUNTIFS(Responsibilities!$H:$H,A13,Responsibilities!$G:$G,"Algorithm step") -> 7 | E13: =C13-D13 -> 0 | F13: v5.1 L2438–2455 | G13: O-14 | H13: O-14 | I13: Assigned | J13: Per cycle kickoff
... A78: Ecological Restoration Algorithm | B78: Extended governance | C78: 8 | D78: =COUNTIFS(Responsibilities!$H:$H,A78,Responsibilities!$G:$G,"Algorithm step") -> 8 | E78: =C78-D78 -> 0 | F78: v5.1 L3979–3996 | G78: G-00 | H78: G-00 | I78: Out of scope for a non-ecological business (human-reserved) | J78: —
A80: 'Steps in Canon' is parsed from versions/v5.1 by build_agent_map.py (numbered lines inside each algorithm section). Canon's Fast-Reference index lists 48 algorithm rows (its footer says 47); the Extended section adds 29 → 77, matching canon's '70+'.

Sheet Canon Element Coverage
A1: Element Key | B1: Canon Element | C1: Source | D1: Canon Location | E1: Owner Agent | F1: Responsibilities Mapped | G1: Covered?
A2: DEPT:STR:Vision | B2: Own the 'Vision' function of the 1 · Strategy Hub (Constitution + founding law). | C2: Nine Departments map — primary function | D2: v5.1 L1378 | E2: STR-01 | F2: =COUNTIF(Responsibilities!$E:$E,A2) -> 1 | G2: =IF(F2>0,"YES","GAP") -> YES
A3: DEPT:STR:Mission | B3: Own the 'Mission' function of the 1 · Strategy Hub (Constitution + founding law). | C3: Nine Departments map — primary function | D3: v5.1 L1378 | E3: STR-01 | F3: =COUNTIF(Responsibilities!$E:$E,A3) -> 1 | G3: =IF(F3>0,"YES","GAP") -> YES
A4: DEPT:STR:Values | B4: Own the 'Values' function of the 1 · Strategy Hub (Constitution + founding law). | C4: Nine Departments map — primary function | D4: v5.1 L1378 | E4: STR-02 | F4: =COUNTIF(Responsibilities!$E:$E,A4) -> 1 | G4: =IF(F4>0,"YES","GAP") -> YES
A5: DEPT:STR:Governing principles | B5: Own the 'Governing principles' function of the 1 · Strategy Hub (Constitution + founding law). | C5: Nine Departments map — primary function | D5: v5.1 L1378 | E5: STR-02 | F5: =COUNTIF(Responsibilities!$E:$E,A5) -> 1 | G5: =IF(F5>0,"YES","GAP") -> YES
A6: DEPT:STR:Quarterly direction | B6: Own the 'Quarterly direction' function of the 1 · Strategy Hub (Constitution + founding law). | C6: Nine Departments map — primary function | D6: v5.1 L1378 | E6: STR-03 | F6: =COUNTIF(Responsibilities!$E:$E,A6) -> 1 | G6: =IF(F6>0,"YES","GAP") -> YES
A7: DEPT:STR:Competitive positioning | B7: Own the 'Competitive positioning' function of the 1 · Strategy Hub (Constitution + founding law). | C7: Nine Departments map — primary function | D7: v5.1 L1378 | E7: STR-04 | F7: =COUNTIF(Responsibilities!$E:$E,A7) -> 1 | G7: =IF(F7>0,"YES","GAP") -> YES
A8: DEPT:STR:BEAS-row | B8: Self-score the 1 · Strategy Hub on Correctness, Complexity, Patience, Resilience (0 / 0.5 / 1 each) with evidence, and score coordination with the other eight hubs (0–1). | C8: BEAS Scoring Instructions | D8: v5.1 L1396–1404 | E8: STR-00 | F8: =COUNTIF(Responsibilities!$E:$E,A8) -> 1 | G8: =IF(F8>0,"YES","GAP") -> YES
A9: DEPT:MKT:Lead generation | B9: Own the 'Lead generation' function of the 2 · Marketing Hub (Roads + traffic systems). | C9: Nine Departments map — primary function | D9: v5.1 L1379 | E9: MKT-01 | F9: =COUNTIF(Responsibilities!$E:$E,A9) -> 1 | G9: =IF(F9>0,"YES","GAP") -> YES
A10: DEPT:MKT:Traffic | B10: Own the 'Traffic' function of the 2 · Marketing Hub (Roads + traffic systems). | C10: Nine Departments map — primary function | D10: v5.1 L1379 | E10: MKT-02 | F10: =COUNTIF(Responsibilities!$E:$E,A10) -> 1 | G10: =IF(F10>0,"YES","GAP") -> YES
A11: DEPT:MKT:Attention | B11: Own the 'Attention' function of the 2 · Marketing Hub (Roads + traffic systems). | C11: Nine Departments map — primary function | D11: v5.1 L1379 | E11: MKT-03 | F11: =COUNTIF(Responsibilities!$E:$E,A11) -> 1 | G11: =IF(F11>0,"YES","GAP") -> YES
A12: DEPT:MKT:Brand awareness | B12: Own the 'Brand awareness' function of the 2 · Marketing Hub (Roads + traffic systems). | C12: Nine Departments map — primary function | D12: v5.1 L1379 | E12: MKT-04 | F12: =COUNTIF(Responsibilities!$E:$E,A12) -> 1 | G12: =IF(F12>0,"YES","GAP") -> YES
A13: DEPT:MKT:Content distribution | B13: Own the 'Content distribution' function of the 2 · Marketing Hub (Roads + traffic systems). | C13: Nine Departments map — primary function | D13: v5.1 L1379 | E13: MKT-05 | F13: =COUNTIF(Responsibilities!$E:$E,A13) -> 1 | G13: =IF(F13>0,"YES","GAP") -> YES
... A183: UPDATE:Protocol | B183: Document Update Protocol: when evidence narrows a business variable, record the narrowing, the newly opened variables, and load it as substrate for the next cycle (never silently overwrite). | C183: Document Update Protocol | D183: v5.1 L204–222 | E183: G-01 | F183: =COUNTIF(Responsibilities!$E:$E,A183) -> 1 | G183: =IF(F183>0,"YES","GAP") -> YES

Sheet BEAS Accountability
A1: BEAS — Business Equilibrium Adherence Score (45-point monthly assessment)
A2: Yellow cells: enter 0 (absent), 0.5 (partial) or 1 (fully implemented); coordination 0–1. Row 16 is an illustrative EXAMPLE and is not counted. Source: v5.1 L1389–1446.
A4: Department | B4: Accountable Lead | C4: Correctness | D4: Correctness Agent | E4: Complexity | F4: Complexity Agent | G4: Patience | H4: Patience Agent | I4: Resilience | J4: Resilience Agent | K4: Dept Total /4 | L4: Coordination /1 | M4: Quadrant
A5: 1 · Strategy Hub | B5: STR-00 | D5: STR-02 | F5: STR-03 | H5: STR-01 | J5: STR-05 | K5: =SUM(C5,E5,G5,I5) -> 0 | M5: High Yin
A6: 2 · Marketing Hub | B6: MKT-00 | D6: MKT-03 | F6: MKT-02 | H6: MKT-00 | J6: MKT-01 | K6: =SUM(C6,E6,G6,I6) -> 0 | M6: High Yang
A7: 3 · Sales Hub | B7: SAL-00 | D7: SAL-09 | F7: SAL-07 | H7: SAL-12 | J7: SAL-03 | K7: =SUM(C7,E7,G7,I7) -> 0 | M7: High Yang
A8: 4 · Operations Hub | B8: OPS-00 | D8: OPS-02 | F8: OPS-03 | H8: OPS-03 | J8: OPS-04 | K8: =SUM(C8,E8,G8,I8) -> 0 | M8: High Yang
A9: 5 · Finance Hub | B9: FIN-00 | D9: FIN-04 | F9: FIN-03 | H9: FIN-02 | J9: FIN-01 | K9: =SUM(C9,E9,G9,I9) -> 0 | M9: High Yin
A10: 6 · HR & Culture Hub | B10: HRC-00 | D10: HRC-04 | F10: HRC-06 | H10: HRC-01 | J10: HRC-10 | K10: =SUM(C10,E10,G10,I10) -> 0 | M10: High Yin
A11: 7 · Technology Hub | B11: TEC-00 | D11: OPS-02 | F11: TEC-04 | H11: TEC-01 | J11: TEC-08 | K11: =SUM(C11,E11,G11,I11) -> 0 | M11: Bridging
A12: 8 · Client Success Hub | B12: CS-00 | D12: CS-03 | F12: CS-04 | H12: CS-10 | J12: CS-08 | K12: =SUM(C12,E12,G12,I12) -> 0 | M12: Bridging
A13: 9 · Content Hub | B13: CON-00 | D13: CON-03 | F13: CON-01 | H13: CON-05 | J13: CON-08 | K13: =SUM(C13,E13,G13,I13) -> 0 | M13: High Yin
A14: TOTALS | C14: =SUM(C5:C13) -> 0 | E14: =SUM(E5:E13) -> 0 | G14: =SUM(G5:G13) -> 0 | I14: =SUM(I5:I13) -> 0 | K14: =SUM(K5:K13) -> 0 | L14: =SUM(L5:L13) -> 0
A16: EXAMPLE (not counted) | B16: SAL-00 | C16: 1 | E16: 0.5 | G16: 0.5 | I16: 0 | K16: =SUM(C16,E16,G16,I16) -> 2 | L16: 0.5 | M16: High Yang
A18: BEAS Total /45 | B18: =K14+L14 -> 0
A19: Band | B19: =IF(COUNT(C5:C13,E5:E13,G5:G13,I5:I13)=0,"Not yet scored",IF(B18>=40,"Dynamic Middle—Sustained",IF(B18>=32,"Equilibrium—Functional",IF(B18>=24,"Imbalance—Managed",IF(B18>=16,"Imbalance—Exposed","Collapse Risk"))))) -> Not yet scored
A20: Canon action | B20: =IF(B19="Not yet scored","—",IF(B18>=40,"Scale intentionally. Begin next Fibonacci step. (O-04 → STR-03)",IF(B18>=32,"Identify lowest-scoring department. Apply Shepherd's Way. (O-04 → O-03)",IF(B18>=24,"Gap analysis. Prioritize by dependency order. (O-04 → O-03)",IF(B18>=16,"Return to Gather. Full Immersion Model recommended. (O-03)","Emergency blueprint session. Minimum viable docs in 9 depts within 30 days. (O-19 + G-00)"))))) -> —
A21: Lowest department total | B21: =IF(B19="Not yet scored","—",INDEX(A5:A13,MATCH(MIN(K5:K13),K5:K13,0))) -> —
A22: High Yang quadrant avg /4 | B22: =AVERAGE(K6:K8) -> 0
A23: High Yin quadrant avg /4 | B23: =AVERAGE(K5,K9,K10,K13) -> 0
A24: Bridging quadrant avg /4 | B24: =AVERAGE(K11:K12) -> 0
A26: Pillar evidence (what 'fully implemented' looks like) — v5.1 L1362–1367
A27: Correctness | B27: Every move objectively sound; no shortcuts (97% accuracy → 16% perfection over 60 decisions). In practice: documented SOPs, tested automations before launch, blueprint review before any build, every Komodo recording. (Pillar steward: OPS-02)
A28: Complexity | B28: Embrace full scope; never oversimplify. In practice: nine integrated departments, no isolated tools, Gather step before any build. (Pillar steward: TEC-04)
A29: Patience | B29: Growth through position, not desperation; blueprint first. In practice: 5-phase implementation, Direct → Guide → Gather before any system is built, quarterly BEAS assessment. (Pillar steward: O-03)
A30: Resilience | B30: Survive pressure without collapse; productive entropy. In practice: Komodo-recorded processes, full documentation, never fully dependent on any single third party, downgrade path to $297. (Pillar steward: STR-05)

Sheet Workflows
A1: Workflow ID | B1: Workflow | C1: Seq | D1: Agent ID | E1: Agent Name | F1: Action | G1: Hands Off To
A2: W01 | B2: Lead-to-Cash (ACE Acquisition → Creation) | C2: 1 | D2: O-01 | E2: =IFERROR(INDEX('Agent Roster'!$B:$B,MATCH(D2,'Agent Roster'!$A:$A,0)),"(group / any)") -> Intake & Triage Agent (Layer 0 Base Code) | F2: Input arrives (ad, form, referral) | G2: MKT-03
A3: W01 | B3: Lead-to-Cash (ACE Acquisition → Creation) | C3: 2 | D3: MKT-03 | E3: =IFERROR(INDEX('Agent Roster'!$B:$B,MATCH(D3,'Agent Roster'!$A:$A,0)),"(group / any)") -> Lead Capture, Tagging & Channel ROI Agent | F3: Capture in Lead Connector; tag source/campaign/hot buttons | G3: SAL-01
A4: W01 | B4: Lead-to-Cash (ACE Acquisition → Creation) | C4: 3 | D4: SAL-01 | E4: =IFERROR(INDEX('Agent Roster'!$B:$B,MATCH(D4,'Agent Roster'!$A:$A,0)),"(group / any)") -> Instant Response Agent | F4: Instant automated first contact (Flows AI) → Contacted | G4: SAL-02
A5: W01 | B5: Lead-to-Cash (ACE Acquisition → Creation) | C5: 4 | D5: SAL-02 | E5: =IFERROR(INDEX('Agent Roster'!$B:$B,MATCH(D5,'Agent Roster'!$A:$A,0)),"(group / any)") -> Lead Qualification Agent | F5: Short-survey qualification → Qualified | G5: SAL-04
A6: W01 | B6: Lead-to-Cash (ACE Acquisition → Creation) | C6: 5 | D6: SAL-04 | E6: =IFERROR(INDEX('Agent Roster'!$B:$B,MATCH(D6,'Agent Roster'!$A:$A,0)),"(group / any)") -> Appointment & Show-Rate Agent | F6: Book and confirm call → Appointment Set / Show | G6: SAL-05
A7: W01 | B7: Lead-to-Cash (ACE Acquisition → Creation) | C7: 6 | D7: SAL-05 | E7: =IFERROR(INDEX('Agent Roster'!$B:$B,MATCH(D7,'Agent Roster'!$A:$A,0)),"(group / any)") -> Sales Call Copilot (7-Step Script) | F7: Pre-call brief; human closer runs 7-step script | G7: SAL-06
A8: W01 | B8: Lead-to-Cash (ACE Acquisition → Creation) | C8: 7 | D8: SAL-06 | E8: =IFERROR(INDEX('Agent Roster'!$B:$B,MATCH(D8,'Agent Roster'!$A:$A,0)),"(group / any)") -> Objection Handling Coach (I.A.C.E.) | F8: I.A.C.E. on objections | G8: SAL-07
A9: W01 | B9: Lead-to-Cash (ACE Acquisition → Creation) | C9: 8 | D9: SAL-07 | E9: =IFERROR(INDEX('Agent Roster'!$B:$B,MATCH(D9,'Agent Roster'!$A:$A,0)),"(group / any)") -> Offer Architect | F9: Present three-tier stack; prospect self-selects | G9: SAL-08
A10: W01 | B10: Lead-to-Cash (ACE Acquisition → Creation) | C10: 9 | D10: SAL-08 | E10: =IFERROR(INDEX('Agent Roster'!$B:$B,MATCH(D10,'Agent Roster'!$A:$A,0)),"(group / any)") -> Proposal & Contract Generator | F10: Draft proposal/contract from notes → Proposal | G10: G-00
A11: W01 | B11: Lead-to-Cash (ACE Acquisition → Creation) | C11: 10 | D11: G-00 | E11: =IFERROR(INDEX('Agent Roster'!$B:$B,MATCH(D11,'Agent Roster'!$A:$A,0)),"(group / any)") -> Founder / Operator (HUMAN) | F11: Human approves and signs | G11: SAL-11
A12: W01 | B12: Lead-to-Cash (ACE Acquisition → Creation) | C12: 11 | D12: SAL-11 | E12: =IFERROR(INDEX('Agent Roster'!$B:$B,MATCH(D12,'Agent Roster'!$A:$A,0)),"(group / any)") -> Sales-to-Onboarding Handoff Agent | F12: Closed Won → handoff package with full context | G12: FIN-07
A13: W01 | B13: Lead-to-Cash (ACE Acquisition → Creation) | C13: 12 | D13: FIN-07 | E13: =IFERROR(INDEX('Agent Roster'!$B:$B,MATCH(D13,'Agent Roster'!$A:$A,0)),"(group / any)") -> Capital Flow Accounting & Collections Agent | F13: Invoice and record payment | G13: FIN-05
... A109: W15 | B109: Agent fleet change | C109: 6 | D109: G-04 | E109: =IFERROR(INDEX('Agent Roster'!$B:$B,MATCH(D109,'Agent Roster'!$A:$A,0)),"(group / any)") -> Framework Compliance Auditor | F109: Audit first runs | G109: — (cycle closes)

Sheet Human Gates
A1: Gate ID | B1: Decision Agents Must Escalate | C1: Raised By | D1: Basis | E1: Canon Location | F1: Decides
A2: HG-01 | B2: Any material decision (the choice itself) | C2: O-16 | D2: Framework cannot supply the choice | E2: v5.1 L172 | F2: G-00
A3: HG-02 | B3: Naming the outcome after an action (e.g., 'success', 'failure') | C3: Any | D3: Framework cannot supply the naming | E3: v5.1 L174 | F3: G-00
A4: HG-03 | B4: Situation-specific measurements an agent cannot take | C4: G-03 | D4: Framework cannot supply empirical measurements | E4: v5.1 L176 | F4: G-00
A5: HG-04 | B5: Stance on a held-open variable / any stipulation | C5: G-01 | D5: Stipulations are operator choices (v5.3) | E5: v5.3 §2 | F5: G-00
A6: HG-05 | B6: Strategic Direct (intent) for hub-level builds | C6: O-03 | D6: Direct begins from Third-Kingdom awareness | E6: v5.1 L1488–1497 | F6: G-00
A7: HG-06 | B7: Sales conversation (Creation stage) | C7: SAL-05 | D7: 'The human magic happens here' | E7: v5.1 L1603 | F7: G-00
A8: HG-07 | B8: Honest escalation / walk-away on an objection or negotiation | C8: SAL-06; SAL-10 | D8: Eliminate or Escalate — the honest path | E8: v5.1 L1637; L2589 | F8: G-00
A9: HG-08 | B9: Contract signature; final negotiated terms | C9: SAL-08; SAL-10 | D9: Derived (commitment) | E9: Derived | F9: G-00
A10: HG-09 | B10: Price and offer changes | C10: FIN-06; SAL-07 | D10: Derived (commercial authority) | E10: Derived | F10: G-00
A11: HG-10 | B11: Capital deployment; budget approval | C11: FIN-01; FIN-02 | D11: Derived (capital authority) | E11: Derived | F11: G-00
A12: HG-11 | B12: Hire, compensation, employment decisions | C12: HRC-01; HRC-02; HRC-04 | D12: Derived (employment law/ethics) | E12: Derived | F12: G-00
